Workbook

Sheet Hoja1
A1: ESTATUS | B1: FECHA DE CAPTURA | C1: Folio SIAC | D1: PAGO PROMOTOR | E1: PAGO GERENTE | F1: MOROSIDAD | G1: NOMBRE PROMOTOR | H1: FECHA POSTEO | I1: PAQUETE | J1: LINEA CONTRATADA | K1: AREA | L1: ESTRATEGIA | M1: CLAVE PROMOTOR | N1: ORDEN DE SERVICIO | O1: TELEFONO | P1: IENDA | Q1: ETAPA PISA | R1: TEL PAGO | S1: TIPO DE CLIENTE | T1: ZONA | U1: Observaciones Telmex | V1: DISTRITO | W1: COLONIA
A2: POSTEADA | B2: 46036 | C2: 151295869 | D2: =IFERROR(SUMIF(Servicios_Promotores!$B:$B,C2,Servicios_Promotores!$R:$R),0) -> 0 | E2: =IFERROR(SUMIF(Pago_GERE!$B:$B,C2,Pago_GERE!$R:$R),0) -> 0 | F2: =IFERROR(SUMIF(Hoja2!$H:$H,C2,Hoja2!$U:$U),0) -> 0 | G2: =IFERROR(VLOOKUP(C2,Hoja3!$C:$D,2,FALSE),"") -> 0 | H2: 46038 | I2: PQI37-PAQUETE CONECTES NEGOCIO | J2: LINEA PORTADA | K2: UNIVERSIDAD | L2: 10001013 | M2: 325078 | N2: 21725726 | O2: 5521563650 | P2: CAT XOCHIMILCO | Q2: PF | R2: 5521563650 | S2: COMERCIAL | T2: INBURSA-XOCHIMILCO | V2: SS_0011 | W2: SAN JOSE ZACATEPEC
A3: POSTEADA | B3: 46036 | C3: 151295939 | D3: =IFERROR(SUMIF(Servicios_Promotores!$B:$B,C3,Servicios_Promotores!$R:$R),0) -> 0 | E3: =IFERROR(SUMIF(Pago_GERE!$B:$B,C3,Pago_GERE!$R:$R),0) -> 0 | F3: =IFERROR(SUMIF(Hoja2!$H:$H,C3,Hoja2!$U:$U),0) -> 1891 | G3: =IFERROR(VLOOKUP(C3,Hoja3!$C:$D,2,FALSE),"") -> 0 | H3: 46050 | I3: INF19-PAQUETE 389 | J3: LINEA NUEVA | K3: ERMITA-TLAHUAC | L3: 10001013 | M3: 325078 | N3: 21690558 | O3: 5551311419 | P3: CAT TLAHUAC | Q3: PF | R3: 5551311419 | S3: RESIDENCIAL | T3: TLAHUAC | V3: TW_0001 | W3: TLAXIXILCO
A4: POSTEADA | B4: 46035 | C4: 151292351 | D4: =IFERROR(SUMIF(Servicios_Promotores!$B:$B,C4,Servicios_Promotores!$R:$R),0) -> 0 | E4: =IFERROR(SUMIF(Pago_GERE!$B:$B,C4,Pago_GERE!$R:$R),0) -> 0 | F4: =IFERROR(SUMIF(Hoja2!$H:$H,C4,Hoja2!$U:$U),0) -> 0 | G4: =IFERROR(VLOOKUP(C4,Hoja3!$C:$D,2,FALSE),"") -> 0 | H4: 46044 | I4: PFR24-INFINITUM NEGOCIO 349 | J4: LINEA NUEVA | K4: BALBUENA | L4: 10001013 | M4: 325078 | N4: 21608295 | O4: 5557252453 | P4: CAT BALBUENA | Q4: PF | R4: 5557252453 | S4: COMERCIAL | T4: BALBUENA | V4: BA_0082 | W4: MERCED BALBUENA
A5: POSTEADA | B5: 46035 | C5: 151293880 | D5: =IFERROR(SUMIF(Servicios_Promotores!$B:$B,C5,Servicios_Promotores!$R:$R),0) -> 0 | E5: =IFERROR(SUMIF(Pago_GERE!$B:$B,C5,Pago_GERE!$R:$R),0) -> 0 | F5: =IFERROR(SUMIF(Hoja2!$H:$H,C5,Hoja2!$U:$U),0) -> 997 | G5: =IFERROR(VLOOKUP(C5,Hoja3!$C:$D,2,FALSE),"") -> 0 | H5: 46041 | I5: PQI43-PAQUETE 499 | J5: LINEA PORTADA | K5: BALBUENA | L5: 10001013 | M5: 325078 | N5: 21790454 | O5: 5557252452 | P5: CAT BALBUENA | Q5: PF | R5: 5557252452 | S5: RESIDENCIAL | T5: BALBUENA | V5: BA_0051 | W5: LORENZO BOTURINI
A6: POSTEADA | B6: 46032 | C6: 151288035 | D6: =IFERROR(SUMIF(Servicios_Promotores!$B:$B,C6,Servicios_Promotores!$R:$R),0) -> 0 | E6: =IFERROR(SUMIF(Pago_GERE!$B:$B,C6,Pago_GERE!$R:$R),0) -> 0 | F6: =IFERROR(SUMIF(Hoja2!$H:$H,C6,Hoja2!$U:$U),0) -> 0 | G6: =IFERROR(VLOOKUP(C6,Hoja3!$C:$D,2,FALSE),"") -> 0 | H6: 46035 | I6: PFR39-INFINITUM 349 | J6: LINEA NUEVA | K6: BALBUENA | L6: 10001013 | M6: 325078 | N6: 21574172 | O6: 5543176015 | P6: CAT MALINCHE | Q6: PF | R6: 5543176015 | S6: RESIDENCIAL | T6: BALBUENA | V6: ML_0096 | W6: CENTRO
A7: POSTEADA | B7: 46030 | C7: 151284161 | D7: =IFERROR(SUMIF(Servicios_Promotores!$B:$B,C7,Servicios_Promotores!$R:$R),0) -> 0 | E7: =IFERROR(SUMIF(Pago_GERE!$B:$B,C7,Pago_GERE!$R:$R),0) -> 0 | F7: =IFERROR(SUMIF(Hoja2!$H:$H,C7,Hoja2!$U:$U),0) -> 979 | G7: =IFERROR(VLOOKUP(C7,Hoja3!$C:$D,2,FALSE),"") -> 0 | H7: 46036 | I7: INF19-PAQUETE 389 | J7: LINEA NUEVA | K7: LINDAVISTA | L7: 10001013 | M7: 325078 | N7: 21506817 | O7: 5591749062 | P7: CAT PARQUE VIA | Q7: PF | R7: 5591749062 | S7: RESIDENCIAL | T7: SANTA MARIA-GUERRERO | V7: AP_0030 | W7: MORELOS
A8: POSTEADA | B8: 46030 | C8: 151284228 | D8: =IFERROR(SUMIF(Servicios_Promotores!$B:$B,C8,Servicios_Promotores!$R:$R),0) -> 0 | E8: =IFERROR(SUMIF(Pago_GERE!$B:$B,C8,Pago_GERE!$R:$R),0) -> 0 | F8: =IFERROR(SUMIF(Hoja2!$H:$H,C8,Hoja2!$U:$U),0) -> 0 | G8: =IFERROR(VLOOKUP(C8,Hoja3!$C:$D,2,FALSE),"") -> 0 | H8: 46036 | I8: INF19-PAQUETE 389 | J8: LINEA PORTADA | K8: BALBUENA | L8: 10001013 | M8: 325078 | N8: 21679176 | O8: 5557716381 | P8: CAT MALINCHE | Q8: PF | R8: 5557716381 | S8: RESIDENCIAL | T8: BALBUENA | V8: AG_0143 | W8: LA JOYA
A9: POSTEADA | B9: 46024 | C9: 151273163 | D9: =IFERROR(SUMIF(Servicios_Promotores!$B:$B,C9,Servicios_Promotores!$R:$R),0) -> 0 | E9: =IFERROR(SUMIF(Pago_GERE!$B:$B,C9,Pago_GERE!$R:$R),0) -> 0 | F9: =IFERROR(SUMIF(Hoja2!$H:$H,C9,Hoja2!$U:$U),0) -> 1098 | G9: =IFERROR(VLOOKUP(C9,Hoja3!$C:$D,2,FALSE),"") -> 0 | H9: 46028 | I9: PFR39-INFINITUM 349 | J9: LINEA NUEVA | K9: SOTELO | L9: 10001013 | M9: 325078 | N9: 21402994 | O9: 5581646651 | P9: CAT CUAJIMALPA | Q9: PF | R9: 5581646651 | S9: RESIDENCIAL | T9: CUAJIMALPA-INTERLOMAS | V9: CUJ0108 | W9: CUAJIMALPA
A10: ABIERTA | B10: 46032 | C10: 151288061 | D10: =IFERROR(SUMIF(Servicios_Promotores!$B:$B,C10,Servicios_Promotores!$R:$R),0) -> 0 | E10: =IFERROR(SUMIF(Pago_GERE!$B:$B,C10,Pago_GERE!$R:$R),0) -> 0 | F10: =IFERROR(SUMIF(Hoja2!$H:$H,C10,Hoja2!$U:$U),0) -> 0 | G10: =IFERROR(VLOOKUP(C10,Hoja3!$C:$D,2,FALSE),"") -> 0 | I10: PFR24-INFINITUM NEGOCIO 349 | J10: LINEA NUEVA | K10: UNIVERSIDAD | L10: 10000064 | M10: 326925 | N10: 21562810 | O10: 5556412870 | P10: CAT XOCHIMILCO | Q10: MC | R10: 5556412870 | S10: COMERCIAL | T10: INBURSA-XOCHIMILCO
A11: ABIERTA | B11: 46028 | C11: 151279638 | D11: =IFERROR(SUMIF(Servicios_Promotores!$B:$B,C11,Servicios_Promotores!$R:$R),0) -> 0 | E11: =IFERROR(SUMIF(Pago_GERE!$B:$B,C11,Pago_GERE!$R:$R),0) -> 0 | F11: =IFERROR(SUMIF(Hoja2!$H:$H,C11,Hoja2!$U:$U),0) -> 0 | G11: =IFERROR(VLOOKUP(C11,Hoja3!$C:$D,2,FALSE),"") -> 0 | I11: PFR39-INFINITUM 349 | J11: LINEA NUEVA | K11: ERMITA-TLAHUAC | L11: 10000064 | M11: 326925 | N11: 21458441 | O11: 0000000000 | P11: CAT TLAHUAC | Q11: MC | R11: 0000000000 | S11: RESIDENCIAL | T11: TLAHUAC | V11: NES0061
A12: ABIERTA | B12: 46024 | C12: 151273210 | D12: =IFERROR(SUMIF(Servicios_Promotores!$B:$B,C12,Servicios_Promotores!$R:$R),0) -> 0 | E12: =IFERROR(SUMIF(Pago_GERE!$B:$B,C12,Pago_GERE!$R:$R),0) -> 0 | F12: =IFERROR(SUMIF(Hoja2!$H:$H,C12,Hoja2!$U:$U),0) -> 0 | G12: =IFERROR(VLOOKUP(C12,Hoja3!$C:$D,2,FALSE),"") -> 0 | I12: PQI37-PAQUETE CONECTES NEGOCIO | J12: LINEA NUEVA | K12: BALBUENA | L12: 10000064 | M12: 326925 | N12: 21366500 | O12: 0000000000 | P12: CAT MIXHUCA | Q12: MC | R12: 0000000000 | S12: COMERCIAL | T12: BALBUENA | V12: NES0061
A13: POSTEADA | B13: 46032 | C13: 151288488 | D13: =IFERROR(SUMIF(Servicios_Promotores!$B:$B,C13,Servicios_Promotores!$R:$R),0) -> 0 | E13: =IFERROR(SUMIF(Pago_GERE!$B:$B,C13,Pago_GERE!$R:$R),0) -> 0 | F13: =IFERROR(SUMIF(Hoja2!$H:$H,C13,Hoja2!$U:$U),0) -> 0 | G13: =IFERROR(VLOOKUP(C13,Hoja3!$C:$D,2,FALSE),"") -> 0 | H13: 46038 | I13: PQI43-PAQUETE 499 | J13: LINEA PORTADA | K13: VALLE-SAN JUAN | L13: 10000064 | M13: 326925 | N13: 21563486 | O13: 5586246471 | P13: CAT PORTALES | Q13: PF | R13: 5586246471 | S13: RESIDENCIAL | T13: VALLE | V13: PO_0132 | W13: REFORMA IZTACCIHUATL SUR
A14: POSTEADA | B14: 46031 | C14: 151286563 | D14: =IFERROR(SUMIF(Servicios_Promotores!$B:$B,C14,Servicios_Promotores!$R:$R),0) -> 0 | E14: =IFERROR(SUMIF(Pago_GERE!$B:$B,C14,Pago_GERE!$R:$R),0) -> 0 | F14: =IFERROR(SUMIF(Hoja2!$H:$H,C14,Hoja2!$U:$U),0) -> 0 | G14: =IFERROR(VLOOKUP(C14,Hoja3!$C:$D,2,FALSE),"") -> 0 | H14: 46035 | I14: PQI37-PAQUETE CONECTES NEGOCIO | J14: LINEA PORTADA | K14: UNIVERSIDAD | L14: 10000064 | M14: 326925 | N14: 21622890 | O14: 5555555351 | P14: CAT XOCHIMILCO | Q14: PF | R14: 5555555351 | S14: COMERCIAL | T14: INBURSA-XOCHIMILCO | V14: XO_0062 | W14: BARRIO SAN MARCOS
A15: POSTEADA | B15: 46029 | C15: 151281955 | D15: =IFERROR(SUMIF(Servicios_Promotores!$B:$B,C15,Servicios_Promotores!$R:$R),0) -> 0 | E15: =IFERROR(SUMIF(Pago_GERE!$B:$B,C15,Pago_GERE!$R:$R),0) -> 0 | F15: =IFERROR(SUMIF(Hoja2!$H:$H,C15,Hoja2!$U:$U),0) -> 1070 | G15: =IFERROR(VLOOKUP(C15,Hoja3!$C:$D,2,FALSE),"") -> 0 | H15: 46031 | I15: PQI42-PAQUETE 435 | J15: LINEA NUEVA | K15: UNIVERSIDAD | L15: 10000064 | M15: 326925 | N15: 21482115 | O15: 5555558619 | P15: CAT XOCHIMILCO | Q15: PF | R15: 5555558619 | S15: RESIDENCIAL | T15: INBURSA-XOCHIMILCO | V15: XO_0193 | W15: PUEBLO SANTA CRUZ XOCHITEPEC
A16: POSTEADA | B16: 46029 | C16: 151280950 | D16: =IFERROR(SUMIF(Servicios_Promotores!$B:$B,C16,Servicios_Promotores!$R:$R),0) -> 0 | E16: =IFERROR(SUMIF(Pago_GERE!$B:$B,C16,Pago_GERE!$R:$R),0) -> 0 | F16: =IFERROR(SUMIF(Hoja2!$H:$H,C16,Hoja2!$U:$U),0) -> 0 | G16: =IFERROR(VLOOKUP(C16,Hoja3!$C:$D,2,FALSE),"") -> 0 | H16: 46031 | I16: INF19-PAQUETE 389 | J16: LINEA PORTADA | K16: UNIVERSIDAD | L16: 10000064 | M16: 326925 | N16: 21460315 | O16: 5593879533 | P16: CAT XOCHIMILCO | Q16: PF | R16: 5593879533 | S16: RESIDENCIAL | T16: INBURSA-XOCHIMILCO | V16: XO_0079 | W16: SANTIAGO TEPALCATLALPAN
A17: POSTEADA | B17: 46029 | C17: 151281559 | D17: =IFERROR(SUMIF(Servicios_Promotores!$B:$B,C17,Servicios_Promotores!$R:$R),0) -> 0 | E17: =IFERROR(SUMIF(Pago_GERE!$B:$B,C17,Pago_GERE!$R:$R),0) -> 0 | F17: =IFERROR(SUMIF(Hoja2!$H:$H,C17,Hoja2!$U:$U),0) -> 896 | G17: =IFERROR(VLOOKUP(C17,Hoja3!$C:$D,2,FALSE),"") -> 0 | H17: 46038 | I17: PFR39-INFINITUM 349 | J17: LINEA NUEVA | K17: UNIVERSIDAD | L17: 10000064 | M17: 326925 | N17: 21483063 | O17: 5556413431 | P17: CAT XOCHIMILCO | Q17: PF | R17: 5556413431 | S17: RESIDENCIAL | T17: INBURSA-XOCHIMILCO | V17: XO_0051 | W17: PUEBLO SANTA CRUZ XOCHITEPEC
A18: POSTEADA | B18: 46029 | C18: 151281785 | D18: =IFERROR(SUMIF(Servicios_Promotores!$B:$B,C18,Servicios_Promotores!$R:$R),0) -> 0 | E18: =IFERROR(SUMIF(Pago_GERE!$B:$B,C18,Pago_GERE!$R:$R),0) -> 0 | F18: =IFERROR(SUMIF(Hoja2!$H:$H,C18,Hoja2!$U:$U),0) -> 598 | G18: =IFERROR(VLOOKUP(C18,Hoja3!$C:$D,2,FALSE),"") -> 0 | H18: 46034 | I18: PFR34-INFINITUM 399 | J18: LINEA NUEVA | K18: UNIVERSIDAD | L18: 10000064 | M18: 326925 | N18: 21482357 | O18: 5555559599 | P18: CAT XOCHIMILCO | Q18: PF | R18: 5555559599 | S18: RESIDENCIAL | T18: INBURSA-XOCHIMILCO | V18: XO_0193 | W18: PUEBLO SANTA CRUZ XOCHITEPEC
A19: POSTEADA | B19: 46029 | C19: 151281134 | D19: =IFERROR(SUMIF(Servicios_Promotores!$B:$B,C19,Servicios_Promotores!$R:$R),0) -> 0 | E19: =IFERROR(SUMIF(Pago_GERE!$B:$B,C19,Pago_GERE!$R:$R),0) -> 0 | F19: =IFERROR(SUMIF(Hoja2!$H:$H,C19,Hoja2!$U:$U),0) -> 0 | G19: =IFERROR(VLOOKUP(C19,Hoja3!$C:$D,2,FALSE),"") -> 0 | H19: 46030 | I19: PFR39-INFINITUM 349 | J19: LINEA NUEVA | K19: UNIVERSIDAD | L19: 10000064 | M19: 326925 | N19: 21461756 | O19: 5556413904 | P19: CAT XOCHIMILCO | Q19: PF | R19: 5556413904 | S19: RESIDENCIAL | T19: INBURSA-XOCHIMILCO | V19: XO_0193 | W19: PUEBLO SANTA CRUZ XOCHITEPEC
A20: POSTEADA | B20: 46028 | C20: 151278693 | D20: =IFERROR(SUMIF(Servicios_Promotores!$B:$B,C20,Servicios_Promotores!$R:$R),0) -> 0 | E20: =IFERROR(SUMIF(Pago_GERE!$B:$B,C20,Pago_GERE!$R:$R),0) -> 0 | F20: =IFERROR(SUMIF(Hoja2!$H:$H,C20,Hoja2!$U:$U),0) -> 1021 | G20: =IFERROR(VLOOKUP(C20,Hoja3!$C:$D,2,FALSE),"") -> 0 | H20: 46030 | I20: PQI37-PAQUETE CONECTES NEGOCIO | J20: LINEA NUEVA | K20: UNIVERSIDAD | L20: 10000064 | M20: 326925 | N20: 21434297 | O20: 5559297099 | P20: CAT XOCHIMILCO | Q20: PF | R20: 5559297099 | S20: COMERCIAL | T20: INBURSA-XOCHIMILCO | V20: AD_0003 | W20: PUEBLO SANTA CECILIA TEPETLAPA
A21: POSTEADA | B21: 46028 | C21: 151279087 | D21: =IFERROR(SUMIF(Servicios_Promotores!$B:$B,C21,Servicios_Promotores!$R:$R),0) -> 0 | E21: =IFERROR(SUMIF(Pago_GERE!$B:$B,C21,Pago_GERE!$R:$R),0) -> 0 | F21: =IFERROR(SUMIF(Hoja2!$H:$H,C21,Hoja2!$U:$U),0) -> 0 | G21: =IFERROR(VLOOKUP(C21,Hoja3!$C:$D,2,FALSE),"") -> 0 | H21: 46030 | I21: INF19-PAQUETE 389 | J21: LINEA PORTADA | K21: UNIVERSIDAD | L21: 10000064 | M21: 326925 | N21: 21438310 | O21: 5563772143 | P21: CAT XOCHIMILCO | Q21: PF | R21: 5563772143 | S21: RESIDENCIAL | T21: INBURSA-XOCHIMILCO | V21: AD_0001 | W21: PUEBLO SANTA CECILIA TEPETLAPA
A22: POSTEADA | B22: 46027 | C22: 151277757 | D22: =IFERROR(SUMIF(Servicios_Promotores!$B:$B,C22,Servicios_Promotores!$R:$R),0) -> 0 | E22: =IFERROR(SUMIF(Pago_GERE!$B:$B,C22,Pago_GERE!$R:$R),0) -> 0 | F22: =IFERROR(SUMIF(Hoja2!$H:$H,C22,Hoja2!$U:$U),0) -> 0 | G22: =IFERROR(VLOOKUP(C22,Hoja3!$C:$D,2,FALSE),"") -> 0 | H22: 46028 | I22: PFR39-INFINITUM 349 | J22: LINEA NUEVA | K22: UNIVERSIDAD | L22: 10000064 | M22: 326925 | N22: 21425751 | O22: 5556185394 | P22: CAT UNIVERSIDAD | Q22: PF | R22: 5556185394 | S22: RESIDENCIAL | T22: COAPA-UNIVERSIDAD | V22: IT_0032 | W22: AJUSCO
A23: POSTEADA | B23: 46027 | C23: 151277736 | D23: =IFERROR(SUMIF(Servicios_Promotores!$B:$B,C23,Servicios_Promotores!$R:$R),0) -> 0 | E23: =IFERROR(SUMIF(Pago_GERE!$B:$B,C23,Pago_GERE!$R:$R),0) -> 0 | F23: =IFERROR(SUMIF(Hoja2!$H:$H,C23,Hoja2!$U:$U),0) -> 0 | G23: =IFERROR(VLOOKUP(C23,Hoja3!$C:$D,2,FALSE),"") -> 0 | H23: 46035 | I23: PFR39-INFINITUM 349 | J23: LINEA NUEVA | K23: UNIVERSIDAD | L23: 10000064 | M23: 326925 | N23: 21424046 | O23: 5556184038 | P23: CAT UNIVERSIDAD | Q23: PF | R23: 5556184038 | S23: RESIDENCIAL | T23: COAPA-UNIVERSIDAD | V23: IT_0010 | W23: PEDREGAL DE SANTO DOMINGO
B24: 46024 | C24: 151273360 | D24: =IFERROR(SUMIF(Servicios_Promotores!$B:$B,C24,Servicios_Promotores!$R:$R),0) -> 0 | E24: =IFERROR(SUMIF(Pago_GERE!$B:$B,C24,Pago_GERE!$R:$R),0) -> 0 | F24: =IFERROR(SUMIF(Hoja2!$H:$H,C24,Hoja2!$U:$U),0) -> 0 | G24: =IFERROR(VLOOKUP(C24,Hoja3!$C:$D,2,FALSE),"") -> 0 | I24: PFR39-INFINITUM 349 | J24: LINEA NUEVA | K24: SOTELO | L24: 10000064 | M24: 326925 | N24: 151273360 | P24: CAT CUAJIMALPA | S24: RESIDENCIAL | T24: CUAJIMALPA-INTERLOMAS | U24: NO ELABORADA DOMICILIO INCORRECTO | V24: NES0061
A25: ABIERTA | B25: 46024 | C25: 151273695 | D25: =IFERROR(SUMIF(Servicios_Promotores!$B:$B,C25,Servicios_Promotores!$R:$R),0) -> 0 | E25: =IFERROR(SUMIF(Pago_GERE!$B:$B,C25,Pago_GERE!$R:$R),0) -> 0 | F25: =IFERROR(SUMIF(Hoja2!$H:$H,C25,Hoja2!$U:$U),0) -> 0 | G25: =IFERROR(VLOOKUP(C25,Hoja3!$C:$D,2,FALSE),"") -> 0 | I25: PQI70-PAQUETE 725 | J25: LINEA PORTADA | K25: UNIVERSIDAD | L25: 10000064 | M25: 329069 | N25: 21397197 | O25: 5593710411 | P25: CAT UNIVERSIDAD | Q25: MC | R25: 5593710411 | S25: RESIDENCIAL | T25: COAPA-UNIVERSIDAD
B26: 46024 | C26: 151273616 | D26: =IFERROR(SUMIF(Servicios_Promotores!$B:$B,C26,Servicios_Promotores!$R:$R),0) -> 0 | E26: =IFERROR(SUMIF(Pago_GERE!$B:$B,C26,Pago_GERE!$R:$R),0) -> 0 | F26: =IFERROR(SUMIF(Hoja2!$H:$H,C26,Hoja2!$U:$U),0) -> 0 | G26: =IFERROR(VLOOKUP(C26,Hoja3!$C:$D,2,FALSE),"") -> 0 | I26: INF19-PAQUETE 389 | J26: LINEA NUEVA | K26: SOTELO | L26: 10000064 | M26: 329069 | N26: 151273616 | P26: CAT CUAJIMALPA | S26: RESIDENCIAL | T26: CUAJIMALPA-INTERLOMAS | U26: NO ELABORADA DOMICILIO INCORRECTO | V26: NES0061
A27: POSTEADA | B27: 46031 | C27: 151286333 | D27: =IFERROR(SUMIF(Servicios_Promotores!$B:$B,C27,Servicios_Promotores!$R:$R),0) -> 0 | E27: =IFERROR(SUMIF(Pago_GERE!$B:$B,C27,Pago_GERE!$R:$R),0) -> 0 | F27: =IFERROR(SUMIF(Hoja2!$H:$H,C27,Hoja2!$U:$U),0) -> 498 | G27: =IFERROR(VLOOKUP(C27,Hoja3!$C:$D,2,FALSE),"") -> 0 | H27: 46037 | I27: PFR39-INFINITUM 349 | J27: LINEA NUEVA | K27: BALBUENA | L27: 10001013 | M27: 330804 | N27: 21573430 | O27: 5552445156 | P27: CAT MALINCHE | Q27: PF | R27: 5552445156 | S27: RESIDENCIAL | T27: BALBUENA | V27: ML_0096 | W27: CENTRO
A28: POSTEADA | B28: 46024 | C28: 151272932 | D28: =IFERROR(SUMIF(Servicios_Promotores!$B:$B,C28,Servicios_Promotores!$R:$R),0) -> 0 | E28: =IFERROR(SUMIF(Pago_GERE!$B:$B,C28,Pago_GERE!$R:$R),0) -> 0 | F28: =IFERROR(SUMIF(Hoja2!$H:$H,C28,Hoja2!$U:$U),0) -> 1149 | G28: =IFERROR(VLOOKUP(C28,Hoja3!$C:$D,2,FALSE),"") -> 0 | H28: 46032 | I28: PFR39-INFINITUM 349 | J28: LINEA NUEVA | K28: TOLUCA | L28: 10001013 | M28: 330804 | N28: 21374721 | O28: 5515475993 | P28: CAT LERMA | Q28: PF | R28: 5515475993 | S28: RESIDENCIAL | T28: LERMA | V28: HUX0028 | W28: SAN JUAN BAUTISTA
B29: 46028 | C29: 151278840 | D29: =IFERROR(SUMIF(Servicios_Promotores!$B:$B,C29,Servicios_Promotores!$R:$R),0) -> 0 | E29: =IFERROR(SUMIF(Pago_GERE!$B:$B,C29,Pago_GERE!$R:$R),0) -> 0 | F29: =IFERROR(SUMIF(Hoja2!$H:$H,C29,Hoja2!$U:$U),0) -> 0 | G29: =IFERROR(VLOOKUP(C29,Hoja3!$C:$D,2,FALSE),"") -> 0 | I29: PFR24-INFINITUM NEGOCIO 349 | J29: LINEA NUEVA | K29: ERMITA-TLAHUAC | L29: 10001013 | M29: 330804 | N29: 151278840 | P29: CAT CULHUACAN | S29: COMERCIAL | T29: CULHUACAN | U29: NO ELABORADA ZONA SIN RED | V29: NES0061
B30: 46024 | C30: 151273169 | D30: =IFERROR(SUMIF(Servicios_Promotores!$B:$B,C30,Servicios_Promotores!$R:$R),0) -> 0 | E30: =IFERROR(SUMIF(Pago_GERE!$B:$B,C30,Pago_GERE!$R:$R),0) -> 0 | F30: =IFERROR(SUMIF(Hoja2!$H:$H,C30,Hoja2!$U:$U),0) -> 0 | G30: =IFERROR(VLOOKUP(C30,Hoja3!$C:$D,2,FALSE),"") -> 0 | I30: PFR39-INFINITUM 349 | J30: LINEA NUEVA | K30: SOTELO | L30: 10001013 | M30: 330804 | N30: 151273169 | P30: CAT CUAJIMALPA | S30: RESIDENCIAL | T30: CUAJIMALPA-INTERLOMAS | U30: NO ELABORADA DOMICILIO INCORRECTO | V30: NES0061
B31: 46024 | C31: 151273388 | D31: =IFERROR(SUMIF(Servicios_Promotores!$B:$B,C31,Servicios_Promotores!$R:$R),0) -> 0 | E31: =IFERROR(SUMIF(Pago_GERE!$B:$B,C31,Pago_GERE!$R:$R),0) -> 0 | F31: =IFERROR(SUMIF(Hoja2!$H:$H,C31,Hoja2!$U:$U),0) -> 0 | G31: =IFERROR(VLOOKUP(C31,Hoja3!$C:$D,2,FALSE),"") -> 0 | I31: PFR34-INFINITUM 399 | J31: LINEA NUEVA | K31: SOTELO | L31: 10001013 | M31: 330804 | N31: 151273388 | P31: CAT CUAJIMALPA | S31: RESIDENCIAL | T31: CUAJIMALPA-INTERLOMAS | U31: NO ELABORADA DOMICILIO INCORRECTO | V31: NES0061
A32: ABIERTA | B32: 46046 | C32: 151314582 | D32: =IFERROR(SUMIF(Servicios_Promotores!$B:$B,C32,Servicios_Promotores!$R:$R),0) -> 0 | E32: =IFERROR(SUMIF(Pago_GERE!$B:$B,C32,Pago_GERE!$R:$R),0) -> 0 | F32: =IFERROR(SUMIF(Hoja2!$H:$H,C32,Hoja2!$U:$U),0) -> 0 | G32: =IFERROR(VLOOKUP(C32,Hoja3!$C:$D,2,FALSE),"") -> 0 | I32: INF19-PAQUETE 389 | J32: LINEA PORTADA | K32: UNIVERSIDAD | L32: 10001013 | M32: 344154 | N32: 21927505 | O32: 5595731905 | P32: CAT XOCHIMILCO | Q32: MC | R32: 5595731905 | S32: RESIDENCIAL | T32: INBURSA-XOCHIMILCO
A33: ABIERTA | B33: 46030 | C33: 151284457 | D33: =IFERROR(SUMIF(Servicios_Promotores!$B:$B,C33,Servicios_Promotores!$R:$R),0) -> 0 | E33: =IFERROR(SUMIF(Pago_GERE!$B:$B,C33,Pago_GERE!$R:$R),0) -> 0 | F33: =IFERROR(SUMIF(Hoja2!$H:$H,C33,Hoja2!$U:$U),0) -> 0 | G33: =IFERROR(VLOOKUP(C33,Hoja3!$C:$D,2,FALSE),"") -> 0 | I33: PFR34-INFINITUM 399 | J33: LINEA NUEVA | K33: BALBUENA | L33: 10001013 | M33: 344154 | N33: 21508498 | O33: 5557892461 | P33: CAT MALINCHE | Q33: MC | R33: 5557892461 | S33: RESIDENCIAL | T33: BALBUENA
A34: POSTEADA | B34: 46046 | C34: 151314622 | D34: =IFERROR(SUMIF(Servicios_Promotores!$B:$B,C34,Servicios_Promotores!$R:$R),0) -> 0 | E34: =IFERROR(SUMIF(Pago_GERE!$B:$B,C34,Pago_GERE!$R:$R),0) -> 0 | F34: =IFERROR(SUMIF(Hoja2!$H:$H,C34,Hoja2!$U:$U),0) -> 0 | G34: =IFERROR(VLOOKUP(C34,Hoja3!$C:$D,2,FALSE),"") -> 0 | H34: 46048 | I34: PFR24-INFINITUM NEGOCIO 349 | J34: LINEA NUEVA | K34: UNIVERSIDAD | L34: 10001013 | M34: 344154 | N34: 21926998 | O34: 5552053001 | P34: CAT XOCHIMILCO | Q34: PF | R34: 5552053001 | S34: COMERCIAL | T34: INBURSA-XOCHIMILCO | V34: SS_0002 | W34: SAN LUCAS XOCHIMANCA
A35: POSTEADA | B35: 46046 | C35: 151314606 | D35: =IFERROR(SUMIF(Servicios_Promotores!$B:$B,C35,Servicios_Promotores!$R:$R),0) -> 0 | E35: =IFERROR(SUMIF(Pago_GERE!$B:$B,C35,Pago_GERE!$R:$R),0) -> 0 | F35: =IFERROR(SUMIF(Hoja2!$H:$H,C35,Hoja2!$U:$U),0) -> 0 | G35: =IFERROR(VLOOKUP(C35,Hoja3!$C:$D,2,FALSE),"") -> 0 | H35: 46048 | I35: PFR24-INFINITUM NEGOCIO 349 | J35: LINEA NUEVA | K35: UNIVERSIDAD | L35: 10001013 | M35: 344154 | N35: 21934517 | O35: 5552053186 | P35: CAT XOCHIMILCO | Q35: PF | R35: 5552053186 | S35: COMERCIAL | T35: INBURSA-XOCHIMILCO | V35: SS_0008 | W35: SAN MATEO XALPA
A36: POSTEADA | B36: 46035 | C36: 151293463 | D36: =IFERROR(SUMIF(Servicios_Promotores!$B:$B,C36,Servicios_Promotores!$R:$R),0) -> 0 | E36: =IFERROR(SUMIF(Pago_GERE!$B:$B,C36,Pago_GERE!$R:$R),0) -> 0 | F36: =IFERROR(SUMIF(Hoja2!$H:$H,C36,Hoja2!$U:$U),0) -> 0 | G36: =IFERROR(VLOOKUP(C36,Hoja3!$C:$D,2,FALSE),"") -> 0 | H36: 46036 | I36: PQI43-PAQUETE 499 | J36: LINEA PORTADA | K36: UNIVERSIDAD | L36: 10001013 | M36: 344154 | N36: 21619146 | O36: 5556443647 | P36: CAT PLAZA INBURSA | Q36: PF | R36: 5556443647 | S36: RESIDENCIAL | T36: INBURSA-XOCHIMILCO | V36: HP_0084 | W36: SAN NICOLAS TOTOLAPAN
A37: POSTEADA | B37: 46035 | C37: 151293510 | D37: =IFERROR(SUMIF(Servicios_Promotores!$B:$B,C37,Servicios_Promotores!$R:$R),0) -> 0 | E37: =IFERROR(SUMIF(Pago_GERE!$B:$B,C37,Pago_GERE!$R:$R),0) -> 0 | F37: =IFERROR(SUMIF(Hoja2!$H:$H,C37,Hoja2!$U:$U),0) -> 0 | G37: =IFERROR(VLOOKUP(C37,Hoja3!$C:$D,2,FALSE),"") -> 0 | H37: 46038 | I37: PFR39-INFINITUM 349 | J37: LINEA NUEVA | K37: UNIVERSIDAD | L37: 10001013 | M37: 344154 | N37: 21619784 | O37: 5556444677 | P37: CAT PLAZA INBURSA | Q37: PF | R37: 5556444677 | S37: RESIDENCIAL | T37: INBURSA-XOCHIMILCO | V37: HP_0069 | W37: PEDREGAL DE SAN NICOLAS
A38: POSTEADA | B38: 46027 | C38: 151276282 | D38: =IFERROR(SUMIF(Servicios_Promotores!$B:$B,C38,Servicios_Promotores!$R:$R),0) -> 0 | E38: =IFERROR(SUMIF(Pago_GERE!$B:$B,C38,Pago_GERE!$R:$R),0) -> 0 | F38: =IFERROR(SUMIF(Hoja2!$H:$H,C38,Hoja2!$U:$U),0) -> 0 | G38: =IFERROR(VLOOKUP(C38,Hoja3!$C:$D,2,FALSE),"") -> 0 | H38: 46030 | I38: PFR39-INFINITUM 349 | J38: LINEA NUEVA | K38: SOTELO | L38: 10000064 | M38: 344157 | N38: 21404976 | O38: 5581643421 | P38: CAT CUAJIMALPA | Q38: PF | R38: 5581643421 | S38: RESIDENCIAL | T38: CUAJIMALPA-INTERLOMAS | V38: SP_0003 | W38: SAN PABLO CHIMALPA
A39: ABIERTA | B39: 46032 | C39: 151288175 | D39: =IFERROR(SUMIF(Servicios_Promotores!$B:$B,C39,Servicios_Promotores!$R:$R),0) -> 0 | E39: =IFERROR(SUMIF(Pago_GERE!$B:$B,C39,Pago_GERE!$R:$R),0) -> 0 | F39: =IFERROR(SUMIF(Hoja2!$H:$H,C39,Hoja2!$U:$U),0) -> 0 | G39: =IFERROR(VLOOKUP(C39,Hoja3!$C:$D,2,FALSE),"") -> 0 | I39: PFR24-INFINITUM NEGOCIO 349 | J39: LINEA NUEVA | K39: UNIVERSIDAD | L39: 10001013 | M39: 345495 | N39: 21562760 | O39: 0000000000 | P39: CAT XOCHIMILCO | Q39: MC | R39: 0000000000 | S39: COMERCIAL | T39: INBURSA-XOCHIMILCO | V39: NES0061
A40: ABIERTA | B40: 46032 | C40: 151288088 | D40: =IFERROR(SUMIF(Servicios_Promotores!$B:$B,C40,Servicios_Promotores!$R:$R),0) -> 0 | E40: =IFERROR(SUMIF(Pago_GERE!$B:$B,C40,Pago_GERE!$R:$R),0) -> 0 | F40: =IFERROR(SUMIF(Hoja2!$H:$H,C40,Hoja2!$U:$U),0) -> 0 | G40: =IFERROR(VLOOKUP(C40,Hoja3!$C:$D,2,FALSE),"") -> 0 | I40: PFR24-INFINITUM NEGOCIO 349 | J40: LINEA NUEVA | K40: TEXCOCO-ZARAGOZA | L40: 10001013 | M40: 345495 | N40: 21576529 | O40: 5554416868 | P40: CAT SANTA MARTHA | Q40: MC | R40: 5554416868 | S40: COMERCIAL | T40: LOS REYES
...

Sheet Hoja3
A1: PISA_E | B1: Fecha | C1: Folio | D1: NOMBRE
A2: POSTEADA | B2: 46037 | C2: 151298098 | D2: ALEJANDRO CORREA
A3: POSTEADA | B3: 46038 | C3: 151300111 | D3: ALEJANDRO CORREA
A4: ABIERTA | B4: 46038 | C4: 151300232 | D4: ALEJANDRO CORREA
A5: ABIERTA | B5: 46038 | C5: 151300277 | D5: ALEJANDRO CORREA
A6: POSTEADA | B6: 46038 | C6: 151300473 | D6: ALEJANDRO CORREA
A7: POSTEADA | B7: 46039 | C7: 151301741 | D7: ALEJANDRO CORREA
B8: 46041 | C8: 151303987 | D8: ALEJANDRO CORREA
A9: POSTEADA | B9: 46041 | C9: 151304427 | D9: ALEJANDRO CORREA
A10: POSTEADA | B10: 46041 | C10: 151304540 | D10: ALEJANDRO CORREA
A11: POSTEADA | B11: 46041 | C11: 151304593 | D11: ALEJANDRO CORREA
A12: POSTEADA | B12: 46041 | C12: 151304676 | D12: ALEJANDRO CORREA
A13: ABIERTA | B13: 46041 | C13: 151304785 | D13: ALEJANDRO CORREA
A14: POSTEADA | B14: 46041 | C14: 151304953 | D14: ALEJANDRO CORREA
A15: POSTEADA | B15: 46041 | C15: 151304957 | D15: ALEJANDRO CORREA
A16: POSTEADA | B16: 46041 | C16: 151304969 | D16: ALEJANDRO CORREA
A17: POSTEADA | B17: 46041 | C17: 151305002 | D17: ALEJANDRO CORREA
A18: POSTEADA | B18: 46042 | C18: 151306053 | D18: ALEJANDRO CORREA
A19: POSTEADA | B19: 46042 | C19: 151306689 | D19: ALEJANDRO CORREA
A20: POSTEADA | B20: 46042 | C20: 151307166 | D20: ALEJANDRO CORREA
... A22: POSTEADA | B22: 46042 | C22: 151307198 | D22: ALEJANDRO CORREA
B23: 46042 | C23: 151307212 | D23: ALEJANDRO CORREA
A24: POSTEADA | B24: 46042 | C24: 151307275 | D24: ALEJANDRO CORREA
A25: POSTEADA | B25: 46042 | C25: 151307389 | D25: ALEJANDRO CORREA
A26: POSTEADA | B26: 46043 | C26: 151309189 | D26: ALEJANDRO CORREA
B27: 46043 | C27: 151309190 | D27: ALEJANDRO CORREA
B28: 46043 | C28: 151309200 | D28: ALEJANDRO CORREA
A29: POSTEADA | B29: 46043 | C29: 151309214 | D29: ALEJANDRO CORREA
A30: POSTEADA | B30: 46043 | C30: 151309258 | D30: ALEJANDRO CORREA
B31: 46043 | C31: 151309309 | D31: ALEJANDRO CORREA
A32: ABIERTA | B32: 46043 | C32: 151309342 | D32: ALEJANDRO CORREA
B33: 46043 | C33: 151309387 | D33: ALEJANDRO CORREA
A34: POSTEADA | B34: 46043 | C34: 151309423 | D34: ALEJANDRO CORREA
A35: POSTEADA | B35: 46043 | C35: 151309427 | D35: ALEJANDRO CORREA
A36: ABIERTA | B36: 46043 | C36: 151309431 | D36: ALEJANDRO CORREA
A37: POSTEADA | B37: 46043 | C37: 151309464 | D37: ALEJANDRO CORREA
A38: POSTEADA | B38: 46044 | C38: 151309793 | D38: ALEJANDRO CORREA
A39: POSTEADA | B39: 46044 | C39: 151310699 | D39: ALEJANDRO CORREA
A40: ABIERTA | B40: 46044 | C40: 151310857 | D40: ALEJANDRO CORREA
A41: ABIERTA | B41: 46044 | C41: 151311031 | D41: ALEJANDRO CORREA
...

Sheet Hoja2
A1: MASTER | B1: EMPRESA | C1: NOMBRE_TUTOR | D1: SUBDIRECCION | E1: AREA | F1: TELEFONO | G1: FECHA_POSTEO | H1: FOLIO_SIAC | I1: OS | J1: TIPO_SERV | K1: NOMBRE_CLIENTE | L1: CAT | M1: CIUDAD | N1: ESTRATEGIA | O1: GERENTE | P1: ORGANIZACIÓN | Q1: PROMOTOR | R1: ESTATUS_PROMOTOR | S1: PAQUETE | T1: MESES_ADEUDO | U1: ADEUDO | V1: IMPORTE_PAGOS | W1: DIA_VENCIMIENTO_RECIBO | X1: TELCONTACTO | Y1: TELCELULAR | Z1: CORREO | AA1: DIRECCION | AB1: DIA_MAYOR_TRAF | AC1: HORA_MAYOR_TRAF
A2: 710 | B2: MARNA IMAGEN CREATIVA | C2: CRISTINA RUIZ | D2: METRO SUR | E2: UNIVERSIDAD | F2: 5517174025 | G2: 46044 | H2: 151309427 | I2: 21872548 | J2: NO RESIDENCIAL | K2: SANDRA AVILES SANTIAGO | L2: CAT COAPA | M2: CIUDAD DE MEXICO | N2: 10001013 | O2: EDGAR DAVID LOVERA JUAREZ | P2: Zuriel | Q2: 345495 | R2: INACTIVO | S2: Naked Neg 50 | T2: 1 | U2: 898 | V2: 1298 | W2: 18 | X2: 5549802499 | Y2: 5571676481 | Z2: sandra.avsan31@gmail.com | AA2: PLAN DE TUXTEPEC 25 XOCHIMILCO SAN LORENZO LA CEBADA 16035 | AB2: Jueves (4) | AC2: 18
A3: 710 | B3: MARNA IMAGEN CREATIVA | C3: CRISTINA RUIZ | D3: METRO SUR | E3: UNIVERSIDAD | F3: 5521575388 | G3: 46029 | H3: 151270009 | I3: 21328223 | J3: RESIDENCIAL | K3: ALONSO ESPINO SHEYLA ANAHI | L3: CAT XOCHIMILCO | M3: CIUDAD DE MEXICO | N3: 10001013 | O3: EDGAR DAVID LOVERA JUAREZ | P3: Zuriel | Q3: 344154 | R3: INACTIVO | S3: Naked $439 | T3: 4 | U3: 2525 | V3: 0 | W3: 4 | X3: 5576068360 | Y3: 5531065345 | Z3: sheylaalonso76@gmail.com | AA3: TERCERA CERRADA DE XOCHITL 79 XOCHIMILCO AMPLIACION NATIVITAS 16459 | AB3: Friday | AC3: 15
A4: 710 | B4: MARNA IMAGEN CREATIVA | C4: CRISTINA RUIZ | D4: METRO SUR | E4: UNIVERSIDAD | F4: 5522930282 | G4: 46029 | H4: 151268375 | I4: 21305402 | J4: RESIDENCIAL | K4: IBARRA ROMERO NATALYEE | L4: CAT XOCHIMILCO | M4: CIUDAD DE MEXICO | N4: 10000064 | O4: EDGAR DAVID LOVERA JUAREZ | P4: Zuriel | Q4: 326925 | R4: INACTIVO | S4: Paq. $479 (50 Mb) | T4: 4 | U4: 1571 | V4: 400 | W4: 4 | X4: 5522193689 | Y4: 5514178474 | Z4: ibarrarromeron@hotmail.com | AA4: 16 DE SEPTIEMBRE 0 XOCHIMILCO BARRIO EL ROSARIO 16070 | AB4: Martes (2) | AC4: 15
A5: 710 | B5: MARNA IMAGEN CREATIVA | C5: CRISTINA RUIZ | D5: METRO NORTE | E5: TEXCOCO-ZARAGOZA | F5: 5526326714 | G5: 46071 | H5: 151355954 | I5: 22413180 | J5: NO RESIDENCIAL | K5: CANDIDO ORTIZ GONZALEZ | L5: CAT LOS REYES (MEX) | M5: MEXICO | N5: 10001013 | O5: EDGAR DAVID LOVERA JUAREZ | P5: Zuriel | Q5: 345495 | R5: INACTIVO | S5: Naked Neg 50 | T5: 2 | U5: 999 | V5: 0 | W5: 14 | X5: 5637886409 | Y5: 5631528055 | Z5: armando.agui1824@gmail.com | AA5: RIO GRIJALVA 012 LA PAZ SAN JOSE LAS PALMAS 56512 | AB5: Jueves (4) | AC5: 13
A6: 710 | B6: MARNA IMAGEN CREATIVA | C6: CRISTINA RUIZ | D6: METRO NORTE | E6: ERMITA-TLAHUAC | F6: 5558866785 | G6: 46068 | H6: 151345444 | I6: 22290885 | J6: NO RESIDENCIAL | K6: DIEGO RODRIGO NOVELO SANCHEZ | L6: CAT CHALCO | M6: MEXICO | N6: 10000064 | O6: EDGAR DAVID LOVERA JUAREZ | P6: Zuriel | Q6: 346072 | R6: INACTIVO | S6: Naked Neg 250 ($499) | T6: 2 | U6: 1498 | V6: 0 | W6: 9 | X6: 5531519531 | Y6: 5514962605 | Z6: hlr290988@gmail.com | AA6: 1ERA CADA LOS ARENALES 33 CHALCO SAN PABLO ATLAZALPAN 56620
A7: 710 | B7: MARNA IMAGEN CREATIVA | C7: CRISTINA RUIZ | D7: METRO SUR | E7: UNIVERSIDAD | F7: 5555558619 | G7: 46031 | H7: 151281955 | I7: 21482115 | J7: RESIDENCIAL | K7: CRUZ PEREA NIDIA | L7: CAT XOCHIMILCO | M7: CIUDAD DE MEXICO | N7: 10000064 | O7: EDGAR DAVID LOVERA JUAREZ | P7: Zuriel | Q7: 326925 | R7: INACTIVO | S7: Paq. $435 (60 Mb) | T7: 1 | U7: 1070 | V7: 1917 | W7: 6 | X7: 5636140755 | Y7: 5530779440 | Z7: nidia_32@live.com.mx | AA7: CERRADA ROSA 0 XOCHIMILCO SANTA CRUZ XOCHITEPEC 16100 | AB7: Jueves (4) | AC7: 19
A8: 710 | B8: MARNA IMAGEN CREATIVA | C8: CRISTINA RUIZ | D8: METRO NORTE | E8: ERMITA-TLAHUAC | F8: 5596484584 | G8: 46032 | H8: 151272743 | I8: 21361873 | J8: RESIDENCIAL | K8: ESPINOZA MATA JULIO CESAR | L8: CAT BOSQUES | M8: CIUDAD DE MEXICO | N8: 10000064 | O8: EDGAR DAVID LOVERA JUAREZ | P8: Zuriel | Q8: 345974 | R8: INACTIVO | S8: Paq. $479 (50 Mb) | T8: 1 | U8: 389 | V8: 784 | W8: 5 | X8: 5645972945 | Y8: 5526971446 | Z8: espinozamatacesar5@gmail.com
A9: 710 | B9: MARNA IMAGEN CREATIVA | C9: CRISTINA RUIZ | D9: METRO NORTE | E9: BALBUENA | F9: 5517161708 | G9: 46079 | H9: 151373288 | I9: 22598508 | J9: RESIDENCIAL | K9: MORALES HERNANDEZ RAFAEL | L9: CAT MIXHUCA | M9: CIUDAD DE MEXICO | N9: 10000064 | O9: EDGAR DAVID LOVERA JUAREZ | P9: Zuriel | Q9: 346126 | R9: INACTIVO | S9: Paq. $479 (50 Mb) | T9: 2 | U9: 1009 | V9: 0 | W9: 23 | X9: 5528237208 | Y9: 5616182400 | Z9: rafaelmoraleshernades04@gmail.com | AA9: BENITO GOMEZ FARIAS SM 4 IZTACALCO CAMPAMENTO 2 DE OCTUBRE 08930 | AB9: Martes (2) | AC9: 10
A10: 710 | B10: MARNA IMAGEN CREATIVA | C10: CRISTINA RUIZ | D10: METRO SUR | E10: UNIVERSIDAD | F10: 5511137312 | G10: 46032 | H10: 151279447 | I10: 21459682 | J10: RESIDENCIAL | K10: HERNANDEZ REZA JOSE MAURICIO | L10: CAT XOCHIMILCO | M10: CIUDAD DE MEXICO | N10: 10000064 | O10: EDGAR DAVID LOVERA JUAREZ | P10: Zuriel | Q10: 345974 | R10: INACTIVO | S10: Naked $439 | T10: 4 | U10: 1149 | V10: 0 | W10: 6 | X10: 5512991933 | Y10: 5510720129 | Z10: mauriciohernandez134161@gmail.com | AA10: HOMBRES ILUSTRES 84 XOCHIMILCO SANTA CECILIA TEPETLAPA 16880 | AB10: Martes (2) | AC10: 16
A11: 710 | B11: MARNA IMAGEN CREATIVA | C11: CRISTINA RUIZ | D11: METRO SUR | E11: SOTELO | F11: 5516613670 | G11: 46086 | H11: 151384631 | I11: 22764779 | J11: RESIDENCIAL | K11: RAMIREZ ROBLES JONATHAN | L11: CAT CUAJIMALPA | M11: CIUDAD DE MEXICO | N11: 10000064 | O11: EDGAR DAVID LOVERA JUAREZ | P11: Zuriel | Q11: 351040 | R11: INACTIVO | S11: Paq. $479 (50 Mb) | T11: 2 | U11: 1353 | V11: 0 | W11: 4 | X11: 5539731535 | Y11: 5656828223 | Z11: jonathanbrenda427@gmail.com | AA11: LA ESCONDIDA 15 ALVARO OBREGON SANTA ROSA XOCHIAC 01830 | AB11: Viernes (5) | AC11: 21
A12: 710 | B12: MARNA IMAGEN CREATIVA | C12: CRISTINA RUIZ | D12: METRO SUR | E12: UNIVERSIDAD | F12: 5521563088 | G12: 46035 | H12: 151292731 | I12: 21615152 | J12: NO RESIDENCIAL | K12: LESLIE JOCCELIN CAMACHO SALAZA | M12: CIUDAD DE MEXICO | N12: 10000064 | O12: EDGAR DAVID LOVERA JUAREZ | P12: Zuriel | Q12: 346072 | R12: INACTIVO | S12: Pq. Conectes Neg | T12: 3 | U12: 1881 | V12: 0 | W12: 8 | X12: 5648812688 | Y12: 5637114441 | Z12: cataleyasalazar91@gmail.com | AB12: Domingo (7) | AC12: 15
A13: 710 | B13: MARNA IMAGEN CREATIVA | C13: CRISTINA RUIZ | D13: ESTADO DE MEXICO | E13: TOLUCA | F13: 5515475993 | G13: 46032 | H13: 151272932 | I13: 21374721 | J13: RESIDENCIAL | K13: LOPEZ GONZALEZ PATRICIA | L13: CAT LERMA | M13: MEXICO | N13: 10001013 | O13: EDGAR DAVID LOVERA JUAREZ | P13: Zuriel | Q13: 330804 | R13: INACTIVO | S13: Naked $439 | T13: 4 | U13: 1149 | V13: 0 | W13: 7 | X13: 5547220967 | Y13: 5547220967 | Z13: plopezgonzalez434@gmail.com | AA13: LOMA DE LOS CEDROS 454 HUIXQUILUCAN SAN JUAN YAUTEPEC 52768 | AB13: Friday | AC13: 19
A14: 710 | B14: MARNA IMAGEN CREATIVA | C14: CRISTINA RUIZ | D14: METRO SUR | E14: UNIVERSIDAD | F14: 5556413431 | G14: 46038 | H14: 151281559 | I14: 21483063 | J14: RESIDENCIAL | K14: RUIZ GONZALEZ FLOR | L14: CAT XOCHIMILCO | M14: CIUDAD DE MEXICO | N14: 10000064 | O14: EDGAR DAVID LOVERA JUAREZ | P14: Zuriel | Q14: 326925 | R14: INACTIVO | S14: Naked $439 | T14: 1 | U14: 896 | V14: 1300 | W14: 11 | X14: 5626666827 | Y14: 5543753734 | Z14: flor.ruizz153@gmail.com | AA14: COMERCIO 14 XOCHIMILCO SANTA CRUZ XOCHITEPEC 16100 | AB14: Viernes (5) | AC14: 19
A15: 710 | B15: MARNA IMAGEN CREATIVA | C15: CRISTINA RUIZ | D15: METRO NORTE | E15: ERMITA-TLAHUAC | F15: 5558434222 | G15: 46111 | H15: 151428398 | I15: 23901714 | J15: RESIDENCIAL | K15: SANTIAGO REYES GLORIA | L15: CAT TLAHUAC | M15: CIUDAD DE MEXICO | N15: 10001013 | O15: EDGAR DAVID LOVERA JUAREZ | P15: Zuriel | Q15: 348467 | R15: INACTIVO | S15: Paq. $479 (50 Mb) | T15: 1 | U15: 1390 | V15: 0 | W15: 27 | X15: 5647678984 | Y15: 5647678984 | Z15: arasantiago.hdz@gmail.com | AA15: CLAVEL 6 XOCHIMILCO SAN GREGORIO ATLAPULCO 16600 | AB15: Viernes (5) | AC15: 15
A16: 710 | B16: MARNA IMAGEN CREATIVA | C16: CRISTINA RUIZ | D16: METRO SUR | E16: MIXCOAC | F16: 5521563494 | G16: 46092 | H16: 151364539 | I16: 22500822 | J16: RESIDENCIAL | K16: MONZON LARA ISAAC IVAN | L16: CAT XOCHIMILCO | M16: CIUDAD DE MEXICO | N16: 10001013 | O16: EDGAR DAVID LOVERA JUAREZ | P16: Zuriel | Q16: 348467 | R16: INACTIVO | S16: Naked $439 | T16: 1 | U16: 849 | V16: 0 | W16: 5 | X16: 5546831566 | Y16: 5544815083 | Z16: monzonivan10@gmail.com | AA16: PINO 5 XOCHIMILCO SANTA CRUZ DE GUADALUPE 16860 | AB16: Jueves (4) | AC16: 23
A17: 710 | B17: MARNA IMAGEN CREATIVA | C17: CRISTINA RUIZ | D17: METRO SUR | E17: UNIVERSIDAD | F17: 5559495884 | G17: 46025 | H17: 151268190 | I17: 21305034 | J17: RESIDENCIAL | K17: SOLARES ROMERO CRISTINA ARELI | L17: CAT XOCHIMILCO | M17: CIUDAD DE MEXICO | N17: 10000064 | O17: EDGAR DAVID LOVERA JUAREZ | P17: Zuriel | Q17: 344157 | R17: INACTIVO | S17: Paq. $479 (50 Mb) | T17: 4 | U17: 1565 | V17: 0 | W17: 30 | X17: 5551450717 | Y17: 5619116786 | Z17: bquero271@gmail.com | AA17: 2DA CERRADA DE 22 DE OCTUBRE NATIVITAS 61 XOCHIMILCO SANTA MARIA NATIVITAS 16450 | AB17: Thursday | AC17: 19
A18: 710 | B18: MARNA IMAGEN CREATIVA | C18: CRISTINA RUIZ | D18: METRO NORTE | E18: TEXCOCO-ZARAGOZA | F18: 5592769414 | G18: 46046 | H18: 151310699 | I18: 21893011 | J18: RESIDENCIAL | K18: BADILLO ACOSTA RAUL | L18: CAT NEZAHUALCOYOTL | M18: MEXICO | N18: 10001013 | O18: EDGAR DAVID LOVERA JUAREZ | P18: Zuriel | Q18: 325078 | R18: INACTIVO | S18: Paq. $479 (50 Mb) | T18: 3 | U18: 1537 | V18: 0 | W18: 20 | X18: 5585766399 | Y18: 5621736861 | Z18: raulacosta201386@gmail.com | AA18: CALLE 1 12 NEZAHUALCOYOTL EL SOL 57200
A19: 710 | B19: MARNA IMAGEN CREATIVA | C19: CRISTINA RUIZ | D19: METRO SUR | E19: UNIVERSIDAD | F19: 5524605274 | G19: 46045 | H19: 151311461 | I19: 21896851 | J19: RESIDENCIAL | K19: MILLAN FLORES YAZMIN | L19: CAT XOCHIMILCO | M19: CIUDAD DE MEXICO | N19: 10000064 | O19: EDGAR DAVID LOVERA JUAREZ | P19: Zuriel | Q19: 346072 | R19: INACTIVO | S19: Naked $439 | T19: 3 | U19: 2096 | V19: 0 | W19: 18 | X19: 5521564252 | Y19: 5534183545 | Z19: alika_2551@yahoo.com.mx | AA19: HUEYOTITLA 3 XOCHIMILCO SAN LUCAS XOCHIMANCA 16300 | AB19: Sabado (6) | AC19: 21
A20: 710 | B20: MARNA IMAGEN CREATIVA | C20: CRISTINA RUIZ | D20: METRO SUR | E20: MIXCOAC | F20: 5559209854 | G20: 46065 | H20: 151340227 | I20: 22225190 | J20: RESIDENCIAL | K20: QUIENTERO PEREZ MARIA DEL CARM | L20: CAT MIXCOAC | M20: CIUDAD DE MEXICO | N20: 10000064 | O20: EDGAR DAVID LOVERA JUAREZ | P20: Zuriel | Q20: 346126 | R20: INACTIVO | S20: Naked $439 | T20: 3 | U20: 949 | V20: 0 | W20: 5 | X20: 5620193196 | Y20: 5610495652 | Z20: mariadelcarmenquintero560@gmail.com | AA20: 1ERA CERRADA 40 ALVARO OBREGON OLIVAR DEL CONDE 1A SECCION 01400 | AB20: Thursday | AC20: 15
A21: 710 | B21: MARNA IMAGEN CREATIVA | C21: CRISTINA RUIZ | D21: METRO SUR | E21: UNIVERSIDAD | F21: 5556184940 | G21: 46118 | H21: 151440375 | I21: 24022834 | J21: RESIDENCIAL | K21: MENDOZA VERA RUBEN | M21: MEXICO | N21: 10001013 | O21: EDGAR DAVID LOVERA JUAREZ | P21: Zuriel | Q21: 348467 | R21: INACTIVO | S21: Naked 50 ($349) | T21: 1 | U21: 1198 | V21: 0 | W21: 28 | X21: 0 | Y21: 5562329740 | Z21: rubendany134@gmail.com
A22: 710 | B22: MARNA IMAGEN CREATIVA | C22: CRISTINA RUIZ | D22: METRO SUR | E22: SOTELO | F22: 5524603795 | G22: 46093 | H22: 151396770 | I22: 22935569 | J22: RESIDENCIAL | K22: PAREDES MONDRAGON YENNIFER | L22: CAT CUAJIMALPA | M22: CIUDAD DE MEXICO | N22: 10000064 | O22: EDGAR DAVID LOVERA JUAREZ | P22: Zuriel | Q22: 350703 | R22: INACTIVO | S22: Paq. $479 (50 Mb) | T22: 1 | U22: 1372 | V22: 0 | W22: 7 | X22: 5593884153 | Y22: 5565435579 | Z22: flaqitamoon33@gmail.com | AA22: CALLE LA GRANJA 43 ALVARO OBREGON SAN BARTOLO AMEYALCO 01800 | AB22: Martes (2) | AC22: 3
A23: 710 | B23: MARNA IMAGEN CREATIVA | C23: CRISTINA RUIZ | D23: METRO SUR | E23: VALLE-SAN JUAN | F23: 5558628679 | G23: 46091 | H23: 151393793 | I23: 22885260 | J23: RESIDENCIAL | K23: LOPEZ LOPES GERARDO | L23: CAT VICTORIA | M23: CIUDAD DE MEXICO | N23: 10000064 | O23: EDGAR DAVID LOVERA JUAREZ | P23: Zuriel | Q23: 350703 | R23: INACTIVO | S23: Paq. $479 (50 Mb) | T23: 1 | U23: 978 | V23: 795 | W23: 5 | X23: 5544367897 | Y23: 5544731194 | Z23: patty.77lopez@gmail.com | AB23: Martes (2) | AC23: 19
A24: 710 | B24: MARNA IMAGEN CREATIVA | C24: CRISTINA RUIZ | D24: METRO SUR | E24: SOTELO | F24: 5581646651 | G24: 46028 | H24: 151273163 | I24: 21402994 | J24: RESIDENCIAL | K24: PACHECO PACHECO FLAVIO | L24: CAT CUAJIMALPA | M24: CIUDAD DE MEXICO | N24: 10001013 | O24: EDGAR DAVID LOVERA JUAREZ | P24: Zuriel | Q24: 325078 | R24: INACTIVO | S24: Naked 50 ($349) | T24: 4 | U24: 1098 | V24: 0 | W24: 3 | X24: 5585701646 | Y24: 5583400687 | Z24: kikamostris@gmail.com | AA24: JUAREZ PONIENTE 29 CUAJIMALPA DE MORELOS CUAJIMALPA 05000 | AB24: Sabado (6) | AC24: 20
A25: 710 | B25: MARNA IMAGEN CREATIVA | C25: CRISTINA RUIZ | D25: METRO SUR | E25: UNIVERSIDAD | F25: 5515606962 | G25: 46092 | H25: 151396798 | I25: 22936702 | J25: NO RESIDENCIAL | K25: ABARROTES VAZQUEZ | L25: CAT XOCHIMILCO | M25: CIUDAD DE MEXICO | N25: 10000064 | O25: EDGAR DAVID LOVERA JUAREZ | P25: Zuriel | Q25: 350703 | R25: INACTIVO | S25: Pq. Conectes Neg | T25: 1 | U25: 899 | V25: 0 | W25: 5 | X25: 5548351700 | Y25: 5538596111 | Z25: veliseo804@gmail.com | AA25: CIRCUITO MARTINEZ DE CASTRO 460 XOCHIMILCO SAN MATEO XALPA 16800 | AB25: Jueves (4) | AC25: 23
A26: 710 | B26: MARNA IMAGEN CREATIVA | C26: CRISTINA RUIZ | D26: METRO SUR | E26: UNIVERSIDAD | F26: 5556538598 | G26: 46118 | H26: 151437578 | I26: 24022053 | J26: RESIDENCIAL | K26: MARTINEZ BELLO PEDRO | L26: CAT XOCHIMILCO | M26: CIUDAD DE MEXICO | N26: 10000064 | O26: EDGAR DAVID LOVERA JUAREZ | P26: Zuriel | Q26: 348485 | R26: ACTIVO | S26: Paq. $479 (50 Mb) | T26: 1 | U26: 1346 | V26: 0 | W26: 28 | X26: 5521940593 | Y26: 5632501936 | Z26: pedro.mtz.bello0520@gmail.com | AA26: CARRETERA A SAN PABLO 525 XOCHIMILCO SANTIAGO TEPALCATLALPAN 16200 | AB26: Viernes (5) | AC26: 18
A27: 710 | B27: MARNA IMAGEN CREATIVA | C27: CRISTINA RUIZ | D27: METRO NORTE | E27: ERMITA-TLAHUAC | F27: 5526073993 | G27: 46059 | H27: 151326581 | I27: 22106183 | J27: RESIDENCIAL | K27: ARREDONDO HERNANDEZ SARA GEORG | L27: CAT CULHUACAN | M27: CIUDAD DE MEXICO | N27: 10000064 | O27: EDGAR DAVID LOVERA JUAREZ | P27: Zuriel | Q27: 346196 | R27: INACTIVO | S27: Paq. $479 (50 Mb) | T27: 1 | U27: 878 | V27: 1344 | W27: 2 | X27: 5541747667 | Y27: 5530414953 | Z27: sararredondoh@gmail.com | AA27: RICARDO MONJES LOPEZ 67 TLAHUAC LOS OLIVOS 13210 | AB27: Martes (2) | AC27: 23
A28: 710 | B28: MARNA IMAGEN CREATIVA | C28: CRISTINA RUIZ | D28: METRO SUR | E28: UNIVERSIDAD | F28: 5556068356 | G28: 46042 | H28: 151304953 | I28: 21824208 | J28: RESIDENCIAL | K28: DOMINGUEZ HERNANDEZ ARTURO | L28: CAT PLAZA INBURSA | M28: CIUDAD DE MEXICO | N28: 10000064 | O28: EDGAR DAVID LOVERA JUAREZ | P28: Zuriel | Q28: 346072 | R28: INACTIVO | S28: Paq. $479 (50 Mb) | T28: 3 | U28: 1095 | V28: 0 | W28: 17 | X28: 5665238960 | Y28: 5657775852 | Z28: arturodominguezhernandes13@gmail.com | AA28: RAYUELA 203 COYOACAN PEDREGAL DE CARRASCO 04700 | AB28: Sabado (6) | AC28: 7
A29: 710 | B29: MARNA IMAGEN CREATIVA | C29: CRISTINA RUIZ | D29: METRO SUR | E29: UNIVERSIDAD | F29: 5550386441 | G29: 46094 | H29: 151397079 | I29: 22930703 | J29: RESIDENCIAL | K29: HERNANDEZ MOLINA DOLORES MICHE | L29: CAT XOCHIMILCO | M29: CIUDAD DE MEXICO | N29: 10000064 | O29: EDGAR DAVID LOVERA JUAREZ | P29: Zuriel | Q29: 348485 | R29: ACTIVO | S29: Naked 50 ($349) | T29: 1 | U29: 449 | V29: 749 | W29: 7 | X29: 5511182530 | Y29: 5511182530 | Z29: danalin76@gmail.com | AA29: CALLE TEPATLA 2 XOCHIMILCO SANTA MARIA TEPEPAN 16020 | AB29: Domingo (7) | AC29: 23
A30: 710 | B30: MARNA IMAGEN CREATIVA | C30: CRISTINA RUIZ | D30: METRO NORTE | E30: BALBUENA | F30: 5517161744 | G30: 46079 | H30: 151373250 | I30: 22598540 | J30: RESIDENCIAL | K30: CERVANTES PORTILLA ALVARO | L30: CAT MIXHUCA | M30: CIUDAD DE MEXICO | N30: 10000064 | O30: EDGAR DAVID LOVERA JUAREZ | P30: Zuriel | Q30: 346126 | R30: INACTIVO | S30: Paq. $479 (50 Mb) | T30: 1 | U30: 978 | V30: 909 | W30: 23 | X30: 5520677092 | Y30: 5541281791 | Z30: rojitohero12@gmail.com | AA30: MIGUEL LERDO TEJADA 190 IZTACALCO CAMPAMENTO 2 DE OCTUBRE 08930 | AB30: Jueves (4) | AC30: 23
A31: 710 | B31: MARNA IMAGEN CREATIVA | C31: CRISTINA RUIZ | D31: METRO NORTE | E31: ERMITA-TLAHUAC | F31: 5558591014 | G31: 46113 | H31: 151436375 | I31: 23983232 | J31: RESIDENCIAL | K31: MEDINA MARTINEZ JORGE | M31: CIUDAD DE MEXICO | N31: 10000064 | O31: EDGAR DAVID LOVERA JUAREZ | P31: Zuriel | Q31: 352529 | R31: ACTIVO | S31: Paq. $479 (50 Mb) | T31: 1 | U31: 1378 | V31: 0 | W31: 27 | X31: 5641040922 | Y31: 5659728309 | Z31: ec5663362@gmail.com | AB31: Lunes (1) | AC31: 0
A32: 710 | B32: MARNA IMAGEN CREATIVA | C32: CRISTINA RUIZ | D32: METRO SUR | E32: UNIVERSIDAD | F32: 5556182777 | G32: 46084 | H32: 151371022 | I32: 22581180 | J32: RESIDENCIAL | K32: SANDOVAL MARQUEZ JOSE LUIS | L32: CAT UNIVERSIDAD | M32: CIUDAD DE MEXICO | N32: 10001013 | O32: EDGAR DAVID LOVERA JUAREZ | P32: Zuriel | Q32: 348467 | R32: INACTIVO | S32: Paq. $479 (50 Mb) | T32: 2 | U32: 1154 | V32: 0 | W32: 30 | X32: 5514818976 | Y32: 5514818976 | Z32: sandoval.joseluis2530@gmail.com | AA32: AZTAQUEMECAN 31 COYOACAN PEDREGAL DE SANTO DOMINGO 04369
A33: 710 | B33: MARNA IMAGEN CREATIVA | C33: CRISTINA RUIZ | D33: METRO NORTE | E33: ERMITA-TLAHUAC | F33: 5528680995 | G33: 46058 | H33: 151324496 | I33: 22046750 | J33: RESIDENCIAL | K33: BRAVO DE LEON YESENIA | L33: CAT TLAHUAC | M33: CIUDAD DE MEXICO | N33: 10000064 | O33: EDGAR DAVID LOVERA JUAREZ | P33: Zuriel | Q33: 346196 | R33: INACTIVO | S33: Paq. $479 (50 Mb) | T33: 2 | U33: 1249 | V33: 0 | W33: 30 | X33: 5662525638 | Y33: 5612030166 | Z33: pumaz.rebel@hotmail.com | AA33: 21 DE MARZO 21 XOCHIMILCO SAN GREGORIO ATLAPULCO 16600 | AB33: Sabado (6) | AC33: 14
A34: 710 | B34: MARNA IMAGEN CREATIVA | C34: CRISTINA RUIZ | D34: METRO SUR | E34: UNIVERSIDAD | F34: 5526157842 | G34: 46094 | H34: 151401517 | I34: 22994224 | J34: RESIDENCIAL | K34: CARRENO GARNICA VANESSA | L34: CAT PLAZA INBURSA | M34: CIUDAD DE MEXICO | N34: 10001013 | O34: EDGAR DAVID LOVERA JUAREZ | P34: Zuriel | Q34: 350677 | R34: INACTIVO | S34: Naked 50 ($349) | T34: 1 | U34: 1298 | V34: 0 | W34: 7 | X34: 5615808500 | Y34: 5615808500 | Z34: maxcruz660@gmail.com | AA34: VENUCIA 117 TLALPAN BELVEDERE AJUSCO 14720 | AB34: Miercoles (3) | AC34: 15
A35: 710 | B35: MARNA IMAGEN CREATIVA | C35: CRISTINA RUIZ | D35: METRO NORTE | E35: TEXCOCO-ZARAGOZA | F35: 5522880404 | G35: 46056 | H35: 151328620 | I35: 22086813 | J35: NO RESIDENCIAL | K35: RICARDO ALARCON SERENO | L35: CAT SANTA MARTHA | M35: CIUDAD DE MEXICO | N35: 10001013 | O35: EDGAR DAVID LOVERA JUAREZ | P35: Zuriel | Q35: 345495 | R35: INACTIVO | S35: Naked Neg 50 | T35: 3 | U35: 1847 | V35: 0 | W35: 27 | X35: 5541308283 | Y35: 5582923196 | Z35: adrianaalejandra775@gmail.com | AA35: FRANCIDSCO LUNA 13 IZTAPALAPA EJERCITO DE AGUA PRIETA 09578 | AB35: Lunes (1) | AC35: 22
A36: 710 | B36: MARNA IMAGEN CREATIVA | C36: CRISTINA RUIZ | D36: METRO SUR | E36: MIXCOAC | F36: 5571585130 | G36: 46078 | H36: 151368923 | I36: 22544193 | J36: RESIDENCIAL | K36: RAMIREZ AGUILAR JUAN CARLOS | L36: CAT CUAJIMALPA | M36: CIUDAD DE MEXICO | N36: 10000064 | O36: EDGAR DAVID LOVERA JUAREZ | P36: Zuriel | Q36: 348485 | R36: ACTIVO | S36: Paq. $479 (50 Mb) | T36: 1 | U36: 394 | V36: 746 | W36: 21 | X36: 5537576166 | Y36: 5526545859 | Z36: charlyaguilar7808@gmail.com | AA36: AGUAJE 1 LA MAGDALENA CONTRERAS EL OCOTAL 10630
A37: 710 | B37: MARNA IMAGEN CREATIVA | C37: CRISTINA RUIZ | D37: METRO SUR | E37: SOTELO | F37: 5592107092 | G37: 46087 | H37: 151373474 | I37: 22598220 | J37: RESIDENCIAL | K37: ARELLANO SALDANA LEONEL | L37: CAT CUAJIMALPA | M37: CIUDAD DE MEXICO | N37: 10000064 | O37: EDGAR DAVID LOVERA JUAREZ | P37: Zuriel | Q37: 348485 | R37: ACTIVO | S37: Paq. $479 (50 Mb) | T37: 2 | U37: 358 | V37: 0 | W37: 4 | X37: 5532418871 | Y37: 5532418871 | Z37: leonel56509@gmail.com | AA37: CDA LA ZANJA 20 CUAJIMALPA DE MORELOS SAN MATEO TLALTENANGO 05600
A38: 710 | B38: MARNA IMAGEN CREATIVA | C38: CRISTINA RUIZ | D38: METRO SUR | E38: LOMAS | F38: 5522235901 | G38: 46060 | H38: 151334592 | I38: 22173583 | J38: RESIDENCIAL | K38: ROSAS SEGUNDO MARIA DE JESUS | L38: CAT BOSQUES | M38: CIUDAD DE MEXICO | N38: 10000064 | O38: EDGAR DAVID LOVERA JUAREZ | P38: Zuriel | Q38: 348485 | R38: ACTIVO | S38: Paq. $389 (50 Mb) | T38: 3 | U38: 1013 | V38: 0 | W38: 4 | X38: 5560999912 | Y38: 5633292020 | Z38: jesusrosassegundo@gmail.com | AA38: CALZ JALALPA 136 ALVARO OBREGON CALZADA JALALPA 01260 | AB38: Martes (2) | AC38: 6
A39: 710 | B39: MARNA IMAGEN CREATIVA | C39: CRISTINA RUIZ | D39: METRO SUR | E39: SOTELO | F39: 5511065039 | G39: 46045 | H39: 151307389 | I39: 21849272 | J39: RESIDENCIAL | K39: PEREZ AGUILAR JOSE LUIS | L39: CAT SOTELO | M39: MEXICO | N39: 10001013 | O39: EDGAR DAVID LOVERA JUAREZ | P39: Zuriel | Q39: 345495 | R39: INACTIVO | S39: Naked 50 ($349) | T39: 3 | U39: 1747 | V39: 0 | W39: 18 | X39: 7121474226 | Y39: 7121474227 | Z39: jl3537280@gmail.com | AA39: JOSE LOPEZ PORTILLO 8 NAUCALPAN DE JUAREZ MARTIRES DE RIO BLANCO 53780
A40: 710 | B40: MARNA IMAGEN CREATIVA | C40: CRISTINA RUIZ | D40: METRO SUR | E40: LINDAVISTA | F40: 5530929161 | G40: 46037 | H40: 151288120 | I40: 21577052 | J40: NO RESIDENCIAL | K40: BRENDA LIZETH LOPEZ SANCHEZ | L40: CAT BELLAS ARTES | M40: CIUDAD DE MEXICO | N40: 10001013 | O40: EDGAR DAVID LOVERA JUAREZ | P40: Zuriel | Q40: 345495 | R40: INACTIVO | S40: Naked Neg 50 | T40: 3 | U40: 1298 | V40: 0 | W40: 12 | X40: 5577632446 | Y40: 5658041996 | Z40: _iguana@hotmail.com | AA40: GALEANA 27 CUAUHTEMOC GUERRERO 06300
...

Sheet Servicios_Promotores
A1: vienede | B1: folio | C1: estrategia | D1: Usuario | E1: Gerente | F1: promotor | G1: tel_pago | H1: os_cargo | I1: pisa_osfposteo | J1: pisa_baja_fecha | K1: division | L1: area | M1: comision_base | N1: pago_comision | O1: pago_distrito | P1: pago_max_10_dias | Q1: pago_directo_promotor | R1: pago_total | S1: pago_paquete | T1: observaciones | U1: rezago | V1: volumen | W1: avance_quincena | X1: rango_volumen | Y1: semana | Z1: archivo_origen
A2: SIAC 2P | B2: 151375639 | C2: 10001013 | D2: TCSRLOJE | E2: EDGAR DAVID LOVERA JUAREZ | F2: 350677 | G2: 5524665760 | H2: 22623094 | I2: 0000-00-00 | K2: METRO-SUR | L2: SOTELO | M2: 50 | N2: 0 | O2: 50 | P2: 0 | Q2: 0 | R2: 50 | S2: INFINITUM SOLO INTERNET 349 | T2: PAGO CLIENTE | U2: 10001013 | Y2: 14-2026 | Z2: Servicios-promotores14-2026.csv
A3: SIAC 2P | B3: 151428449 | C3: 10000064 | D3: TCSRLOJE | E3: EDGAR DAVID LOVERA JUAREZ | F3: 348485 | G3: 5552760252 | H3: 23872387 | I3: 0000-00-00 | K3: METRO-SUR | L3: MIXCOAC | M3: 250 | N3: 250 | O3: 0 | P3: 0 | Q3: 0 | R3: 250 | S3: PAQUETE 389 | T3: POSTEO | U3: 10000064 | Y3: 14-2026 | Z3: Servicios-promotores14-2026.csv
A4: SIAC 2P | B4: 151419967 | C4: 10000064 | D4: TCSRLOJE | E4: EDGAR DAVID LOVERA JUAREZ | F4: 348485 | G4: 5558416979 | H4: 23788939 | I4: 0000-00-00 | K4: METRO-SUR | L4: ERMITA-TLAHUAC | M4: 250 | N4: 250 | O4: 0 | P4: 0 | Q4: 0 | R4: 250 | S4: INFINITUM SOLO INTERNET 349 | T4: POSTEO | U4: 10000064 | Y4: 14-2026 | Z4: Servicios-promotores14-2026.csv
A5: SIAC 2P | B5: 151419851 | C5: 10000064 | D5: TCSRLOJE | E5: EDGAR DAVID LOVERA JUAREZ | F5: 348485 | G5: 5558415444 | H5: 23788517 | I5: 0000-00-00 | K5: METRO-SUR | L5: ERMITA-TLAHUAC | M5: 250 | N5: 250 | O5: 0 | P5: 0 | Q5: 0 | R5: 250 | S5: INFINITUM SOLO INTERNET 349 | T5: POSTEO | U5: 10000064 | Y5: 14-2026 | Z5: Servicios-promotores14-2026.csv
A6: SIAC 2P | B6: 151417029 | C6: 10001013 | D6: TCSRLOJE | E6: EDGAR DAVID LOVERA JUAREZ | F6: 345495 | G6: 5558107022 | H6: 23802224 | I6: 0000-00-00 | K6: METRO-SUR | L6: METROPOLITANA | M6: 250 | N6: 250 | O6: 0 | P6: 0 | Q6: 0 | R6: 250 | S6: PAQUETE 389 | T6: POSTEO | U6: 10001013 | Y6: 14-2026 | Z6: Servicios-promotores14-2026.csv
A7: SIAC 2P | B7: 151413164 | C7: 10000064 | D7: TCSRLOJE | E7: EDGAR DAVID LOVERA JUAREZ | F7: 352529 | G7: 5595608513 | H7: 23437284 | I7: 0000-00-00 | K7: METRO-SUR | L7: METROPOLITANA | M7: 250 | N7: 250 | O7: 0 | P7: 0 | Q7: 0 | R7: 250 | S7: PAQUETE INFINITUM NEGOCIO 649 | T7: POSTEO | U7: 10000064 | Y7: 14-2026 | Z7: Servicios-promotores14-2026.csv
A8: SIAC 2P | B8: 151388573 | C8: 10001013 | D8: TCSRLOJE | E8: EDGAR DAVID LOVERA JUAREZ | F8: 351030 | G8: 5521569682 | H8: 22923355 | I8: 0000-00-00 | K8: METRO-SUR | L8: METROPOLITANA | M8: 50 | N8: 0 | O8: 50 | P8: 0 | Q8: 0 | R8: 50 | S8: PAQUETE 389 | T8: PAGO CLIENTE | U8: 10001013 | Y8: 14-2026 | Z8: Servicios-promotores14-2026.csv
A9: SIAC 2P | B9: 151384434 | C9: 10000064 | D9: TCSRLOJE | E9: EDGAR DAVID LOVERA JUAREZ | F9: 346072 | G9: 5551626672 | H9: 22759030 | I9: 0000-00-00 | K9: METRO-SUR | L9: UNIVERSIDAD | M9: 50 | N9: 0 | O9: 50 | P9: 0 | Q9: 0 | R9: 50 | S9: INFINITUM SOLO INTERNET 449 | T9: PAGO CLIENTE | U9: 10000064 | Y9: 14-2026 | Z9: Servicios-promotores14-2026.csv
A10: SIAC 2P | B10: 151381589 | C10: 10001013 | D10: TCSRLOJE | E10: EDGAR DAVID LOVERA JUAREZ | F10: 351030 | G10: 5522085628 | H10: 22726751 | I10: 0000-00-00 | K10: METRO-SUR | L10: UNIVERSIDAD | M10: 50 | N10: 0 | O10: 50 | P10: 0 | Q10: 0 | R10: 50 | S10: PAQUETE 389 | T10: PAGO CLIENTE | U10: 10001013 | Y10: 14-2026 | Z10: Servicios-promotores14-2026.csv
A11: SIAC 2P | B11: 151243535 | C11: 10000064 | D11: TCSRLOJE | E11: EDGAR DAVID LOVERA JUAREZ | F11: 329069 | G11: 5559198037 | H11: 20964375 | I11: 0000-00-00 | K11: METRO-SUR | L11: UNIVERSIDAD | M11: 50 | N11: 0 | O11: 50 | P11: 0 | Q11: 0 | R11: 50 | S11: PAQUETE 389 | T11: PAGO CLIENTE | U11: 10000064 | Y11: 14-2026 | Z11: Servicios-promotores14-2026.csv
A12: SIAC 2P | B12: 151375541 | C12: 10001013 | D12: TCSRLOJE | E12: EDGAR DAVID LOVERA JUAREZ | F12: 350677 | G12: 5593396508 | H12: 22624366 | I12: 0000-00-00 | K12: METRO-SUR | L12: METROPOLITANA | M12: 50 | N12: 0 | O12: 50 | P12: 0 | Q12: 0 | R12: 50 | S12: PAQUETE 389 | T12: PAGO CLIENTE | U12: 10001013 | Y12: 14-2026 | Z12: Servicios-promotores14-2026.csv
A13: SIAC 2P | B13: 151368590 | C13: 10000064 | D13: TCSRLOJE | E13: EDGAR DAVID LOVERA JUAREZ | F13: 346072 | G13: 5591806859 | H13: 22640228 | I13: 0000-00-00 | K13: METRO-SUR | L13: METROPOLITANA | M13: 50 | N13: 0 | O13: 50 | P13: 0 | Q13: 0 | R13: 50 | S13: PAQUETE 435 | T13: PAGO CLIENTE | U13: 10000064 | Y13: 14-2026 | Z13: Servicios-promotores14-2026.csv
... A96: SIAC 2P | B96: 151445934 | C96: 10000064 | D96: TCSRLOJE | E96: EDGAR DAVID LOVERA JUAREZ | F96: 346072 | G96: 5575731937 | H96: 24096896 | I96: 0000-00-00 | K96: METRO-SUR | L96: METROPOLITANA | M96: 250 | N96: 250 | O96: 0 | P96: 0 | Q96: 0 | R96: 250 | S96: PAQUETE 389 | T96: POSTEO | U96: 10000064 | Y96: 16-2026 | Z96: Servicios-promotores16-2026(1).csv
A97: SIAC 2P | B97: 151451990 | C97: 10001013 | D97: TCSRLOJE | E97: EDGAR DAVID LOVERA JUAREZ | F97: 348467 | G97: 5594643293 | H97: 24193581 | I97: 2026-04-15 | K97: METRO-SUR | L97: METROPOLITANA | M97: 250 | N97: 250 | O97: 0 | P97: 0 | Q97: 0 | R97: 250 | S97: PAQUETE 389 | T97: POSTEO | Y97: 17-2026 | Z97: Servicios-promotores17-2026(1).csv
A98: SIAC 2P | B98: 151351958 | C98: 10000064 | D98: TCSRLOJE | E98: EDGAR DAVID LOVERA JUAREZ | F98: 349815 | G98: 5589086222 | H98: 22381211 | I98: 2026-02-16 | K98: METRO-SUR | L98: TEXCOCO-ZARAGOZA | M98: 75 | N98: 0 | O98: 75 | P98: 0 | Q98: 0 | R98: 75 | S98: PAQUETE 389 | T98: PAGO CLIENTE MES 1 | Y98: 17-2026 | Z98: Servicios-promotores17-2026(1).csv
A99: SIAC 2P | B99: 151368821 | C99: 10000064 | D99: TCSRLOJE | E99: EDGAR DAVID LOVERA JUAREZ | F99: 346126 | G99: 5515182302 | H99: 22546164 | I99: 2026-02-25 | K99: METRO-SUR | L99: VALLE-SAN JUAN | M99: 50 | N99: 0 | O99: 50 | P99: 0 | Q99: 0 | R99: 50 | S99: INFINITUM NEGOCIO SOLO INTERNET 499 | T99: DOMICILIACION MES 1 | Y99: 17-2026 | Z99: Servicios-promotores17-2026(1).csv
A100: SIAC 2P | B100: 151375639 | C100: 10001013 | D100: TCSRLOJE | E100: EDGAR DAVID LOVERA JUAREZ | F100: 350677 | G100: 5524665760 | H100: 22623094 | I100: 2026-02-27 | K100: METRO-SUR | L100: SOTELO | M100: 50 | N100: 0 | O100: 50 | P100: 0 | Q100: 0 | R100: 50 | S100: INFINITUM SOLO INTERNET 349 | T100: DOMICILIACION MES 1 | Y100: 17-2026 | Z100: Servicios-promotores17-2026(1).csv
A101: SIAC 2P | B101: 151390991 | C101: 10000064 | D101: TCSRLOJE | E101: EDGAR DAVID LOVERA JUAREZ | F101: 350703 | G101: 5524603793 | H101: 22928596 | I101: 2026-03-12 | K101: METRO-SUR | L101: METROPOLITANA | M101: 75 | N101: 0 | O101: 75 | P101: 0 | Q101: 0 | R101: 75 | S101: PAQUETE 389 | T101: PAGO CLIENTE MES 1 | Y101: 17-2026 | Z101: Servicios-promotores17-2026(1).csv
A102: SIAC 2P | B102: 151399114 | C102: 10000064 | D102: TCSRLOJE | E102: EDGAR DAVID LOVERA JUAREZ | F102: 351037 | G102: 5511137309 | H102: 22954058 | I102: 2026-04-14 | K102: METRO-SUR | L102: UNIVERSIDAD | M102: 250 | N102: 250 | O102: 0 | P102: 0 | Q102: 0 | R102: 250 | S102: INFINITUM SOLO INTERNET 349 | T102: POSTEO | Y102: 17-2026 | Z102: Servicios-promotores17-2026(1).csv
A103: SIAC 2P | B103: 151409781 | C103: 10000064 | D103: TCSRLOJE | E103: EDGAR DAVID LOVERA JUAREZ | F103: 348485 | G103: 5591808238 | H103: 23336253 | I103: 2026-03-20 | K103: METRO-SUR | L103: UNIVERSIDAD | M103: 75 | N103: 0 | O103: 75 | P103: 0 | Q103: 0 | R103: 75 | S103: INFINITUM SOLO INTERNET 349 | T103: PAGO CLIENTE MES 1 | Y103: 17-2026 | Z103: Servicios-promotores17-2026(1).csv
A104: SIAC 2P | B104: 151410686 | C104: 10000064 | D104: TCSRLOJE | E104: EDGAR DAVID LOVERA JUAREZ | F104: 346072 | G104: 5552456331 | H104: 23382543 | I104: 2026-03-20 | K104: METRO-SUR | L104: BALBUENA | M104: 50 | N104: 0 | O104: 50 | P104: 0 | Q104: 0 | R104: 50 | S104: INFINITUM SOLO INTERNET 349 | T104: DOMICILIACION MES 1 | Y104: 17-2026 | Z104: Servicios-promotores17-2026(1).csv
A105: SIAC 2P | B105: 151419967 | C105: 10000064 | D105: TCSRLOJE | E105: EDGAR DAVID LOVERA JUAREZ | F105: 348485 | G105: 5558416979 | H105: 23788939 | I105: 2026-03-24 | K105: METRO-SUR | L105: ERMITA-TLAHUAC | M105: 75 | N105: 0 | O105: 75 | P105: 0 | Q105: 0 | R105: 75 | S105: INFINITUM SOLO INTERNET 349 | T105: PAGO CLIENTE MES 1 | Y105: 17-2026 | Z105: Servicios-promotores17-2026(1).csv
A106: SIAC 2P | B106: 151462960 | C106: 10001013 | D106: TCSRLOJE | E106: EDGAR DAVID LOVERA JUAREZ | F106: 353923 | G106: 5596432717 | H106: 24343153 | I106: 2026-04-18 | K106: METRO-SUR | L106: ECATEPEC | M106: 250 | N106: 250 | O106: 0 | P106: 0 | Q106: 0 | R106: 250 | S106: PAQUETE 389 | T106: POSTEO | Y106: 17-2026 | Z106: Servicios-promotores17-2026(1).csv
A107: SIAC 2P | B107: 151456274 | C107: 10000064 | D107: TCSRLOJE | E107: EDGAR DAVID LOVERA JUAREZ | F107: 346072 | G107: 5524665347 | H107: 24472122 | I107: 2026-04-20 | K107: METRO-SUR | L107: METROPOLITANA | M107: 250 | N107: 250 | O107: 0 | P107: 0 | Q107: 0 | R107: 250 | S107: PAQUETE 389 | T107: POSTEO | Y107: 17-2026 | Z107: Servicios-promotores17-2026(1).csv
A108: SIAC 2P | B108: 151456294 | C108: 10001013 | D108: TCSRLOJE | E108: EDGAR DAVID LOVERA JUAREZ | F108: 353923 | G108: 5581647899 | H108: 24229396 | I108: 2026-04-15 | K108: METRO-SUR | L108: LOMAS | M108: 250 | N108: 250 | O108: 0 | P108: 0 | Q108: 0 | R108: 250 | S108: PAQUETE 389 | T108: POSTEO | Y108: 17-2026 | Z108: Servicios-promotores17-2026(1).csv
... A114: SIAC 2P | B114: 151462935 | C114: 10001013 | D114: TCSRLOJE | E114: EDGAR DAVID LOVERA JUAREZ | F114: 353923 | G114: 5556955318 | H114: 24337685 | I114: 2026-04-17 | K114: METRO-SUR | L114: ERMITA-TLAHUAC | M114: 250 | N114: 250 | O114: 0 | P114: 0 | Q114: 0 | R114: 250 | S114: PAQUETE INFINITUM NEGOCIO 549 | T114: POSTEO | Y114: 17-2026 | Z114: Servicios-promotores17-2026(1).csv
A115: SIAC 2P | B115: 151440807 | C115: 10000064 | D115: TCSRLOJE | E115: EDGAR DAVID LOVERA JUAREZ | F115: 348485 | G115: 5521571022 | H115: 24030778 | I115: 2026-04-06 | K115: METRO-SUR | L115: UNIVERSIDAD | M115: 75 | N115: 0 | O115: 75 | P115: 0 | Q115: 0 | R115: 75 | S115: INFINITUM SOLO INTERNET 349 | T115: PAGO CLIENTE MES 1 | U115: 10000064 | Y115: 18-2026 | Z115: Servicios-promotores18-2026(1).csv
A116: SIAC 2P | B116: 5726560 | C116: 10000064 | D116: TCSRLOJE | E116: EDGAR DAVID LOVERA JUAREZ | F116: 346072 | G116: 6646463041 | H116: 31414235 | I116: 2026-04-27 | K116: NOROESTE | L116: TIJUANA | M116: 250 | N116: 250 | O116: 0 | P116: 0 | Q116: 0 | R116: 250 | S116: PAQUETE 389 | T116: POSTEO | U116: 10001013 | Y116: 18-2026 | Z116: Servicios-promotores18-2026(1).csv
A117: SIAC 2P | B117: 151340019 | C117: 10001013 | D117: TCSRLOJE | E117: EDGAR DAVID LOVERA JUAREZ | F117: 348467 | G117: 5543177159 | H117: 22241475 | I117: 2026-02-09 | K117: METRO-SUR | L117: UNIVERSIDAD | M117: 75 | N117: 0 | O117: 75 | P117: 0 | Q117: 0 | R117: 75 | S117: PAQUETE 389 | T117: PAGO CLIENTE MES 1 | U117: 10000064 | Y117: 18-2026 | Z117: Servicios-promotores18-2026(1).csv
A118: SIAC 2P | B118: 151344986 | C118: 10000064 | D118: TCSRLOJE | E118: EDGAR DAVID LOVERA JUAREZ | F118: 346126 | G118: 5591347168 | H118: 22297238 | I118: 2026-02-23 | K118: METRO-SUR | L118: ERMITA-TLAHUAC | M118: 75 | N118: 0 | O118: 75 | P118: 0 | Q118: 0 | R118: 75 | S118: PAQUETE 389 | T118: PAGO CLIENTE MES 1 | U118: 10001013 | Y118: 18-2026 | Z118: Servicios-promotores18-2026(1).csv
A119: SIAC 2P | B119: 151396936 | C119: 10000064 | D119: TCSRLOJE | E119: EDGAR DAVID LOVERA JUAREZ | F119: 350703 | G119: 5521559507 | H119: 22929376 | I119: 2026-03-12 | K119: METRO-SUR | L119: UNIVERSIDAD | M119: 75 | N119: 0 | O119: 75 | P119: 0 | Q119: 0 | R119: 75 | S119: PAQUETE INFINITUM NEGOCIO 399 | T119: PAGO CLIENTE MES 1 | U119: 10000064 | Y119: 18-2026 | Z119: Servicios-promotores18-2026(1).csv
A120: SIAC 2P | B120: 151409762 | C120: 10001013 | D120: TCSRLOJE | E120: EDGAR DAVID LOVERA JUAREZ | F120: 351030 | G120: 5552445074 | H120: 23378822 | I120: 2026-03-20 | K120: METRO-SUR | L120: BALBUENA | M120: 75 | N120: 0 | O120: 75 | P120: 0 | Q120: 0 | R120: 75 | S120: PAQUETE 389 | T120: PAGO CLIENTE MES 1 | U120: 10000064 | Y120: 18-2026 | Z120: Servicios-promotores18-2026(1).csv
